File: PPMS/CH1 YBCO_LAO CH2 YBCO_STO CH3 1000SIOLOW ENERGY_STO .dat
[Header]
TITLE, default name
FILEOPENTIME, 13991754.64, 6/11/2024, 1:59 PM
BYAPP, Resistivity, 2.0, 1.0
INFO, APPNAME, PPMS MultiVu Application, Release 1.5.0.19
INFO, , Sample1 Name
INFO, 1, Sample1 Cross Section
INFO, 1, Sample1 Length
INFO, Ohm-m, Sample1 Units
INFO, , Sample2 Name
INFO, 1, Sample2 Cross Section
INFO, 1, Sample2 Length
INFO, Ohm-m, Sample2 Units
INFO, , Sample3 Name
INFO, 1, Sample3 Cross Section
INFO, 1, Sample3 Length
INFO, Ohm-m, Sample3 Units
INFO, , Sample4 Name
INFO, 1, Sample4 Cross Section
INFO, 1, Sample4 Length
INFO, Ohm-m, Sample4 Units
FIELDGROUP, Resistivity,2,3,4,5,6,7,8,9,10,11,12,13,14,15,16,17,18,19,20,21,22,23,24,25,26,27,28,29,30,31,32,33,34,35,36,37,38,39,40,41
STARTUPGROUP, Resistivity
STARTUPAXIS, X, 2, LINEAR, AUTO
STARTUPAXIS, Y1, 7, LINEAR, AUTO
STARTUPAXIS, Y2, 9, LINEAR, AUTO
STARTUPAXIS, Y3, 11, LINEAR, AUTO
PLOT_APPEARANCE, ALL, HORZ_GRID_ON, VERT_GRID_ON, MARKERS_AND_LINES, ALL_LINES
DATATYPE, TIME, 2
DATATYPE, COMMENT, 1
[Data]
Comment,Time Stamp (sec),Status (code),Temperature (K),Magnetic Field (Oe),Sample Position (deg),Bridge 1 Resistivity (Ohm-m),Bridge 1 Excitation (uA),Bridge 2 Resistivity (Ohm-m),Bridge 2 Excitation (uA),Bridge 3 Resistivity (Ohm-m),Bridge 3 Excitation (uA),Bridge 4 Resistivity (Ohm-m),Bridge 4 Excitation (uA),Bridge 1 Std. Dev. (Ohm-m),Bridge 2 Std. Dev. (Ohm-m),Bridge 3 Std. Dev. (Ohm-m),Bridge 4 Std. Dev. (Ohm-m),Number of Readings,Bridge 1 Resistance (Ohms),Bridge 2 Resistance (Ohms),Bridge 3 Resistance (Ohms),Bridge 4 Resistance (Ohms),Signal 1 Vin (V),Signal 2 Vin (V),Digital Inputs (code),Drive 1 Iout (mA),Drive 1 Ipower (watts),Drive 2 Iout (mA),Drive 2 Ipower (watts),Pressure (),Map 20 (),Map 21 (),Map 22 (),Map 23 (),Map 24 (),Map 25 (),Map 26 (),Map 27 (),Map 28 (),Map 29 ()
,13992848.73,69906,304.993698120117,-0.0549999997019768,0,0.0232350602722168,0.999000012874603,0.0186665141296387,0.999000012874603,0.249047500610352,0.999000012874603,,,5.83777759110554e-005,2.93965781099255e-005,3.35878774933195e-005,,25,23.2350602722168,18.6665141296387,249.047500610352,,,,,,,,,,23.3816872,18.6361637,442.9448242,
,13992903.72,69910,303.290344238281,-0.0549999997019768,0,0.0231611680603027,0.999000012874603,0.0186286672210693,0.999000012874603,0.248963782348633,0.999000012874603,,,3.66139840598298e-005,2.70634489957114e-005,3.63028874422357e-005,,25,23.1611680603027,18.6286672210693,248.963782348633,,,,,,,,,,23.1843338,18.6503048,442.9448242,
,13992946.27,69906,300.345642089844,-0.0549999997019768,0,0.0229882931518555,0.999000012874603,0.0185103851318359,0.999000012874603,0.248738533325195,0.999000012874603,,,4.39100379345504e-005,2.88119379069193e-005,3.52797970534918e-005,,25,22.9882931518555,18.5103851318359,248.738533325195,,,,,,,,,,22.9415760,18.5375271,442.9448242,
,13993008.06,69906,297.201553344727,-0.0549999997019768,0,0.0227384088897705,0.999000012874603,0.0182546710968018,0.999000012874603,0.248311594238281,0.999000012874603,,,5.37579533776797e-005,8.96540949116136e-005,3.87657849536686e-005,,25,22.7384088897705,18.2546710968018,248.311594238281,,,,,,,,,,22.7977962,18.2405300,442.9448242,
,13993069.86,69906,294.227493286133,-0.0549999997019768,0,0.02255471824646,0.999000012874603,0.0181277474975586,0.999000012874603,0.248106873779297,0.999000012874603,,,3.68818298172284e-005,3.04748032570761e-005,3.23700402343528e-005,,25,22.55471824646,18.1277474975586,248.106873779297,,,,,,,,,,22.5258961,18.1090183,442.9448242,
,13993111.95,69906,292.182006835938,-0.0549999997019768,0,0.0224042949676514,0.999000012874603,0.0180008206176758,0.999000012874603,0.247872756347656,0.999000012874603,,,7.37727418987907e-005,3.55036394412787e-005,3.46298311467241e-005,,25,22.4042949676514,18.0008206176758,247.872756347656,,,,,,,,,,22.4988289,18.0013561,442.9448242,
,13993159.31,69906,289.716156005859,-0.0549999997019768,0,0.0222425814056396,0.999000012874603,0.0178684093475342,0.999000012874603,0.247703727416992,0.999000012874603,,,6.22141220588137e-005,2.4279646409823e-005,3.05659794302433e-005,,25,22.2425814056396,17.8684093475342,247.703727416992,,,,,,,,,,22.3145866,17.8753662,442.9448242,
,13993220.05,69906,286.717010498047,-0.0549999997019768,0,0.0220305213928223,0.999000012874603,0.017700235824585,0.999000012874603,0.24747137878418,0.999000012874603,,,5.11674484323367e-005,3.45830820622609e-005,3.7499424416029e-005,,25,22.0305213928223,17.700235824585,247.47137878418,,,,,,,,,,22.0986347,17.7316551,442.9448242,
,13993280.58,69906,283.707855224609,-0.0549999997019768,0,0.0218183631134033,0.999000012874603,0.0175202143096924,0.999000012874603,0.247154678955078,0.999000012874603,,,4.85973371726168e-005,2.83299003285219e-005,3.01343002549116e-005,,25,21.8183631134033,17.5202143096924,247.154678955078,,,,,,,,,,21.7850342,17.5178452,442.9448242,
,13993340.59,69906,280.701950073242,-0.0549999997019768,0,0.0216049159240723,0.999000012874603,0.0173441773223877,0.999000012874603,0.246981287231445,0.999000012874603,,,4.76950641810451e-005,3.40408223427002e-005,3.25186037848048e-005,,25,21.6049159240723,17.3441773223877,246.981287231445,,,,,,,,,,21.6530800,17.3239937,442.9448242,
,13993400.47,69906,277.709945678711,-0.0549999997019768,0,0.0213971408843994,0.999000012874603,0.017167921295166,0.999000012874603,0.246741665039063,0.999000012874603,,,6.42171878749595e-005,3.09726099449067e-005,3.77904830331997e-005,,25,21.3971408843994,17.167921295166,246.741665039063,,,,,,,,,,21.4255028,17.1484280,442.9448242,
,13993460.78,69906,274.7060546875,-0.0549999997019768,0,0.0211586382293701,0.999000012874603,0.016981749420166,0.999000012874603,0.246460528564453,0.999000012874603,,,4.75257982046675e-005,3.20854774669821e-005,3.07907660551809e-005,,25,21.1586382293701,16.981749420166,246.460528564453,,,,,,,,,,21.2509804,16.9702053,442.9448242,
,13993521.09,69906,271.686798095703,-0.0549999997019768,0,0.0209846630859375,0.999000012874603,0.0168095008850098,0.999000012874603,0.246230626831055,0.999000012874603,,,3.39132113307882e-005,2.3533786057325e-005,2.90475474566641e-005,,25,20.9846630859375,16.8095008850098,246.230626831055,,,,,,,,,,20.9828281,16.7767067,442.9448242,
,13993581.00,69906,268.694549560547,-0.0549999997019768,0,0.0207652956390381,0.999000012874603,0.0166401671600342,0.999000012874603,0.2460008203125,0.999000012874603,,,5.45131946601204e-005,3.46804006220841e-005,2.77327693130315e-005,,25,20.7652956390381,16.6401671600342,246.0008203125,,,,,,,,,,20.7471790,16.6634808,442.9448242,
,13993640.67,69906,265.712295532227,-0.0549999997019768,0,0.020537925491333,0.999000012874603,0.0164507813262939,0.999000012874603,0.245816116943359,0.999000012874603,,,4.09102736751483e-005,2.8417591012922e-005,3.92496940307018e-005,,25,20.537925491333,16.4507813262939,245.816116943359,,,,,,,,,,20.5018444,16.4886208,442.9448242,
,13993701.00,69906,262.682754516602,-0.0549999997019768,0,0.0203315594482422,0.999000012874603,0.0162791596221924,0.999000012874603,0.245660307006836,0.999000012874603,,,6.84939123446827e-005,2.80281531654359e-005,3.08553148154903e-005,,25,20.3315594482422,16.2791596221924,245.660307006836,,,,,,,,,,20.4802361,16.2798481,442.9448242,
,13993760.44,69906,259.704742431641,-0.0549999997019768,0,0.0201259349822998,0.999000012874603,0.0161063272857666,0.999000012874603,0.245532733154297,0.999000012874603,,,6.90997121968399e-005,3.11631991936473e-005,3.19490252523382e-005,,25,20.1259349822998,16.1063272857666,245.532733154297,,,,,,,,,,20.2107849,16.1078568,442.9448242,
,13993819.97,69906,256.732955932617,-0.0549999997019768,0,0.0199364365386963,0.999000012874603,0.0159317356491089,0.999000012874603,0.245396723632812,0.999000012874603,,,5.00380087879063e-005,3.26616279807177e-005,3.24996135114399e-005,,25,19.9364365386963,15.9317356491089,245.396723632813,,,,,,,,,,19.8866711,15.9613190,442.9448242,
,13993871.02,69906,254.173652648926,-0.0549999997019768,0,0.0197379196929932,0.999000012874603,0.0157827209091187,0.999000012874603,0.245309007568359,0.999000012874603,,,4.26844652295097e-005,2.71601761721229e-005,3.08065804305586e-005,,25,19.7379196929932,15.7827209091187,245.309007568359,,,,,,,,,,19.7801991,15.7931948,442.9448242,
,13993930.66,69906,251.173545837402,-0.0549999997019768,0,0.0195413952636719,0.999000012874603,0.0155969723129272,0.999000012874603,0.245233532714844,0.999000012874603,,,4.7086678470533e-005,2.58423205979435e-005,3.49943315161044e-005,,25,19.5413952636719,15.5969723129272,245.233532714844,,,,,,,,,,19.5856590,15.6238050,442.9448242,
,13993990.81,69906,248.186950683594,-0.0549999997019768,0,0.0193215906524658,0.999000012874603,0.0154146723556519,0.999000012874603,0.245149188842773,0.999000012874603,,,5.4650484021078e-005,2.5928538648883e-005,2.29977823897173e-005,,25,19.3215906524658,15.4146723556519,245.149188842773,,,,,,,,,,19.3082867,15.4015217,442.9448242,
,13994050.64,69906,245.18579864502,-0.0549999997019768,0,0.0191087211608887,0.999000012874603,0.0152487891387939,0.999000012874603,0.245010824584961,0.999000012874603,,,5.0815492020969e-005,2.74526125191253e-005,2.86690188550765e-005,,25,19.1087211608887,15.2487891387939,245.010824584961,,,,,,,,,,19.0592651,15.2871599,442.9448242,
,13994099.98,69906,242.726249694824,-0.0549999997019768,0,0.0189437715148926,0.999000012874603,0.0151161734008789,0.999000012874603,0.244964736328125,0.999000012874603,,,3.88322228219523e-005,2.76710151393901e-005,2.36359832000396e-005,,25,18.9437715148926,15.1161734008789,244.964736328125,,,,,,,,,,18.9388790,15.1763287,442.9448242,
,13994149.73,69906,240.244697570801,-0.0549999997019768,0,0.0187847453308105,0.999000012874603,0.0149609091567993,0.999000012874603,0.245049981079102,0.999000012874603,,,4.64074491713511e-005,2.96907141286399e-005,2.49224148335504e-005,,25,18.7847453308105,14.9609091567993,245.049981079102,,,,,,,,,,18.7667809,14.9560938,442.9448242,
,13994200.61,69906,237.698501586914,-0.0549999997019768,0,0.0186089559173584,0.999000012874603,0.0148038325500488,0.999000012874603,0.245081995239258,0.999000012874603,,,5.45998407944188e-005,2.85487436912181e-005,3.49067817392484e-005,,25,18.6089559173584,14.8038325500488,245.081995239258,,,,,,,,,,18.6506920,14.7600336,442.9448242,
,13994259.81,69906,234.736152648926,-0.0549999997019768,0,0.0183865479278564,0.999000012874603,0.0146312787628174,0.999000012874603,0.245122293701172,0.999000012874603,,,4.74395520312321e-005,3.09968759699213e-005,2.72933169355245e-005,,25,18.3865479278564,14.6312787628174,245.122293701172,,,,,,,,,,18.3490963,14.6345654,442.9448242,
,13994310.73,69906,232.188507080078,-0.0549999997019768,0,0.018213288192749,0.999000012874603,0.0144906655502319,0.999000012874603,0.245208099365234,0.999000012874603,,,5.82305881889934e-005,3.16621335470229e-005,3.64665899691909e-005,,25,18.213288192749,14.4906655502319,245.208099365234,,,,,,,,,,18.2408810,14.4459515,442.9448242,
,13994360.47,69906,229.699447631836,-0.0549999997019768,0,0.0180361344146729,0.999000012874603,0.0143467377090454,0.999000012874603,0.245377502441406,0.999000012874603,,,4.97784747297799e-005,2.96014975693672e-005,3.09476100869958e-005,,25,18.0361344146729,14.3467377090454,245.377502441406,,,,,,,,,,18.0353699,14.3663816,442.9448242,
,13994420.55,69906,226.704048156738,-0.0549999997019768,0,0.017840837020874,0.999000012874603,0.0141636720657349,0.999000012874603,0.245569743652344,0.999000012874603,,,5.07274862810392e-005,2.84089552255827e-005,3.08559041207022e-005,,25,17.840837020874,14.1636720657349,245.569743652344,,,,,,,,,,17.9898300,14.2133627,442.9448242,
,13994480.41,69906,223.699554443359,-0.0549999997019768,0,0.0176122933197021,0.999000012874603,0.0139872919464111,0.999000012874603,0.245668141479492,0.999000012874603,,,6.74460076219156e-005,2.16755247121554e-005,2.64730729912935e-005,,25,17.6122933197021,13.9872919464111,245.668141479492,,,,,,,,,,17.5497608,14.0027342,442.9448242,
,13994540.19,69906,220.715850830078,-0.0549999997019768,0,0.0174271927642822,0.999000012874603,0.0138171668624878,0.999000012874603,0.245749659423828,0.999000012874603,,,5.01486047388014e-005,3.32701777219111e-005,3.42623011273291e-005,,25,17.4271927642822,13.8171668624878,245.749659423828,,,,,,,,,,17.4672489,13.8094463,442.9448242,
,13994600.41,69906,217.689300537109,-0.0549999997019768,0,0.0172203085327148,0.999000012874603,0.0136334605407715,0.999000012874603,0.245936943969727,0.999000012874603,,,6.07543754925365e-005,2.68915006729124e-005,3.36672716553544e-005,,25,17.2203085327148,13.6334605407715,245.936943969727,,,,,,,,,,17.2060890,13.6112146,442.9448242,
,13994659.88,69906,214.724945068359,-0.0549999997019768,0,0.0170037431335449,0.999000012874603,0.0134573171615601,0.999000012874603,0.245970407714844,0.999000012874603,,,5.47754727231881e-005,3.00350904070603e-005,2.95117471580611e-005,,25,17.0037431335449,13.4573171615601,245.970407714844,,,,,,,,,,17.0901794,13.5173864,442.9448242,
,13994719.48,69906,211.7314453125,-0.0549999997019768,0,0.016798240814209,0.999000012874603,0.0132822465133667,0.999000012874603,0.246167913818359,0.999000012874603,,,5.20567627672834e-005,2.63904279180469e-005,2.83273352376348e-005,,25,16.798240814209,13.2822465133667,246.167913818359,,,,,,,,,,16.8240013,13.2696342,442.9448242,
,13994771.06,69906,209.154754638672,-0.0549999997019768,0,0.0165977716827393,0.999000012874603,0.0131384847640991,0.999000012874603,0.246314377441406,0.999000012874603,,,4.93840117143544e-005,2.42473303792588e-005,3.62055173360188e-005,,25,16.5977716827393,13.1384847640991,246.314377441406,,,,,,,,,,16.6214390,13.1511555,442.9448242,
,13994830.09,69906,206.205001831055,-0.0549999997019768,0,0.0164021669769287,0.999000012874603,0.0129637256622314,0.999000012874603,0.246511810302734,0.999000012874603,,,5.22337630754216e-005,2.83066334516447e-005,3.70065015965861e-005,,25,16.4021669769287,12.9637256622314,246.511810302734,,,,,,,,,,16.4472561,12.9029179,442.9448242,
,13994890.45,69906,203.18635559082,-0.0549999997019768,0,0.016220506439209,0.999000012874603,0.0127802276992798,0.999000012874603,0.246804795532227,0.999000012874603,,,4.55054929713944e-005,2.42109662472056e-005,4.24824527752307e-005,,25,16.220506439209,12.7802276992798,246.804795532227,,,,,,,,,,16.2469425,12.8076277,442.9448242,
,13994950.00,69906,200.196403503418,-0.0549999997019768,0,0.015981524887085,0.999000012874603,0.0126125946807861,0.999000012874603,0.247133864135742,0.999000012874603,,,4.05044896733417e-005,2.79205076583926e-005,3.21570172307368e-005,,25,15.981524887085,12.6125946807861,247.133864135742,,,,,,,,,,16.0261421,12.6206360,442.9448242,
,13994999.84,69906,197.721252441406,-0.0549999997019768,0,0.015816462097168,0.999000012874603,0.0124584577941895,0.999000012874603,0.247401069335938,0.999000012874603,,,4.99796998147848e-005,3.1159149277908e-005,2.31294388722482e-005,,25,15.816462097168,12.4584577941895,247.401069335938,,,,,,,,,,15.9304361,12.4676304,442.9448242,
,13995060.56,69906,194.686050415039,-0.0549999997019768,0,0.0156233067321777,0.999000012874603,0.0122846605300903,0.999000012874603,0.247767786865234,0.999000012874603,,,4.49796244083543e-005,3.11019590623975e-005,3.40806066005224e-005,,25,15.6233067321777,12.2846605300903,247.767786865234,,,,,,,,,,15.6108475,12.3182182,442.9448242,
,13995119.77,69906,191.723449707031,-0.0549999997019768,0,0.0154038652801514,0.999000012874603,0.0121057508850098,0.999000012874603,0.24805327331543,0.999000012874603,,,5.04399139783667e-005,2.24741297752964e-005,4.14657514835675e-005,,25,15.4038652801514,12.1057508850098,248.05327331543,,,,,,,,,,15.3734426,12.1554346,442.9448242,
,13995170.67,69906,189.181198120117,-0.0549999997019768,0,0.0152335889434814,0.999000012874603,0.0119520705413818,0.999000012874603,0.2483465234375,0.999000012874603,,,5.21673583751973e-005,2.39161793361889e-005,3.42181731886265e-005,,25,15.2335889434814,11.9520705413818,248.3465234375,,,,,,,,,,15.2865629,12.0129194,442.9448242,
,13995230.48,69906,186.182548522949,-0.0549999997019768,0,0.0150248272705078,0.999000012874603,0.0117779946517944,0.999000012874603,0.248781081542969,0.999000012874603,,,4.47762869330025e-005,3.1916488612028e-005,3.87088253717018e-005,,25,15.0248272705078,11.7779946517944,248.781081542969,,,,,,,,,,14.9953184,11.7615576,442.9448242,
,13995290.89,69906,183.16234588623,-0.0549999997019768,0,0.0148283347320557,0.999000012874603,0.0115970232391357,0.999000012874603,0.249169769287109,0.999000012874603,,,4.78190796522644e-005,3.49853817127501e-005,3.08334249644288e-005,,25,14.8283347320557,11.5970232391357,249.169769287109,,,,,,,,,,14.8914013,11.5870848,442.9448242,
,13995349.86,69906,180.209251403809,-0.0549999997019768,0,0.0146116108322144,0.999000012874603,0.0114301110076904,0.999000012874603,0.249621102294922,0.999000012874603,,,4.49577670488122e-005,2.77862077466949e-005,2.6920643769061e-005,,25,14.6116108322144,11.4301110076904,249.621102294922,,,,,,,,,,14.6743755,11.4711637,442.9448242,
,13995409.77,69906,177.214950561523,-0.0549999997019768,0,0.0143969721221924,0.999000012874603,0.0112426705932617,0.999000012874603,0.250075823364258,0.999000012874603,,,4.95705697146291e-005,2.16395525101157e-005,4.35061368483693e-005,,25,14.3969721221924,11.2426705932617,250.075823364258,,,,,,,,,,14.4669952,11.2525320,442.9448242,
,13995460.38,69906,174.693649291992,-0.0549999997019768,0,0.0142316388320923,0.999000012874603,0.0110871224594116,0.999000012874603,0.250420396728516,0.999000012874603,,,3.53892597881658e-005,3.06884618919561e-005,3.985681909938e-005,,25,14.2316388320923,11.0871224594116,250.420396728516,,,,,,,,,,14.2816191,11.0737486,442.9448242,
,13995520.06,69906,171.692604064941,-0.0549999997019768,0,0.0140168352127075,0.999000012874603,0.0109066790390015,0.999000012874603,0.251031415405273,0.999000012874603,,,4.34951988912718e-005,2.34608746333684e-005,4.1413759370855e-005,,25,14.0168352127075,10.9066790390015,251.031415405273,,,,,,,,,,13.9708195,10.9095068,442.9448242,
,13995580.36,69906,168.679649353027,-0.0549999997019768,0,0.0138088957977295,0.999000012874603,0.0107265328216553,0.999000012874603,0.251675139160156,0.999000012874603,,,4.95291050049237e-005,3.12026098503268e-005,3.87086554340766e-005,,25,13.8088957977295,10.7265328216553,251.675139160156,,,,,,,,,,13.6934462,10.8071957,442.9448242,
,13995640.06,69906,165.69450378418,-0.0549999997019768,0,0.0135916913223267,0.999000012874603,0.0105561544418335,0.999000012874603,0.252236797485352,0.999000012874603,,,4.16775862371066e-005,3.08679455888435e-005,3.38801762634525e-005,,25,13.5916913223267,10.5561544418335,252.236797485352,,,,,,,,,,13.6071329,10.5990391,442.9448242,
,13995699.34,69906,162.731895446777,-0.0549999997019768,0,0.0134101351928711,0.999000012874603,0.0103804842376709,0.999000012874603,0.252924491577148,0.999000012874603,,,3.44293882911148e-005,2.72255730240399e-005,4.54771180006888e-005,,25,13.4101351928711,10.3804842376709,252.924491577148,,,,,,,,,,13.3969107,10.3333941,442.9448242,
,13995749.95,69906,160.194046020508,-0.0549999997019768,0,0.0132193324279785,0.999000012874603,0.0102092613983154,0.999000012874603,0.25349276550293,0.999000012874603,,,4.87481991240669e-005,2.63198644604177e-005,4.32481175137127e-005,,25,13.2193324279785,10.2092613983154,253.49276550293,,,,,,,,,,13.2264423,10.2012348,442.9448242,
,13995809.13,69906,157.249099731445,-0.0549999997019768,0,0.0130230433273315,0.999000012874603,0.0100390561294556,0.999000012874603,0.254191583862305,0.999000012874603,,,5.02455580436068e-005,1.87975699167629e-005,4.657121153748e-005,,25,13.0230433273315,10.0390561294556,254.191583862305,,,,,,,,,,12.9953756,10.0680246,442.9448242,
,13995859.89,69906,154.700302124023,-0.0549999997019768,0,0.0128350466918945,0.999000012874603,0.00987556228637695,0.999000012874603,0.254930978393555,0.999000012874603,,,4.88710166630444e-005,2.33931585711767e-005,5.84307611496239e-005,,25,12.8350466918945,9.87556228637695,254.930978393555,,,,,,,,,,12.8501530,9.8196192,442.9448242,
,13995919.58,69906,151.717956542969,-0.0549999997019768,0,0.0126178176879883,0.999000012874603,0.00970158996582031,0.999000012874603,0.255766262207031,0.999000012874603,,,6.21279886398835e-005,3.43237340637546e-005,6.10922903413302e-005,,25,12.6178176879883,9.70158996582031,255.766262207031,,,,,,,,,,12.5757208,9.7322807,442.9448242,
,13995979.78,69906,148.703048706055,-0.0549999997019768,0,0.0124138768005371,0.999000012874603,0.00951890480041504,0.999000012874603,0.256593188476563,0.999000012874603,,,5.33189396149628e-005,2.80442820791994e-005,5.42041280302406e-005,,25,12.4138768005371,9.51890480041504,256.593188476562,,,,,,,,,,12.3749352,9.5616684,442.9448242,
,13996039.66,69906,145.701599121094,-0.0549999997019768,0,0.0121930154418945,0.999000012874603,0.00932024627685547,0.999000012874603,0.257409475097656,0.999000012874603,,,5.66698172415406e-005,2.99384716334027e-005,3.44524184070243e-005,,25,12.1930154418945,9.32024627685547,257.409475097656,,,,,,,,,,12.1941891,9.3253059,442.9448242,
,13996099.77,69906,142.701400756836,-0.0549999997019768,0,0.0119798969650269,0.999000012874603,0.00912940944671631,0.999000012874603,0.258239182128906,0.999000012874603,,,4.22508431252073e-005,2.46866923209276e-005,4.25409437145175e-005,,25,11.9798969650269,9.12940944671631,258.239182128906,,,,,,,,,,12.0452909,9.1749077,442.9448242,
,13996160.25,69906,139.683197021484,-0.0549999997019768,0,0.0117656856155396,0.999000012874603,0.00895036804199219,0.999000012874603,0.259117105712891,0.999000012874603,,,3.89664584245841e-005,3.02921245775006e-005,5.27002564427777e-005,,25,11.7656856155396,8.95036804199219,259.117105712891,,,,,,,,,,11.7287369,8.9408216,442.9448242,
,13996219.97,69906,136.67985534668,-0.0549999997019768,0,0.0115355646514893,0.999000012874603,0.00876058628082275,0.999000012874603,0.260098140869141,0.999000012874603,,,4.25188884967201e-005,2.42348928357623e-005,4.18829191107549e-005,,25,11.5355646514893,8.76058628082275,260.098140869141,,,,,,,,,,11.5343828,8.7730856,442.9448242,
,13996279.84,69906,133.694046020508,-0.0549999997019768,0,0.0113473764419556,0.999000012874603,0.00856334552764893,0.999000012874603,0.260949405517578,0.999000012874603,,,4.47472552164676e-005,3.09108450500923e-005,7.96266451610131e-005,,25,11.3473764419556,8.56334552764893,260.949405517578,,,,,,,,,,11.3435745,8.5750322,442.9448242,
,13996329.80,69906,131.202049255371,-0.0549999997019768,0,0.0111687342453003,0.999000012874603,0.00839201137542725,0.999000012874603,0.261745030517578,0.999000012874603,,,5.14986419294016e-005,2.58804221809001e-005,6.40308355019314e-005,,25,11.1687342453003,8.39201137542725,261.745030517578,,,,,,,,,,11.1361685,8.3803158,442.9448242,
,13996389.52,69906,128.221153259277,-0.0549999997019768,0,0.0109165257263184,0.999000012874603,0.00820891284942627,0.999000012874603,0.262746058349609,0.999000012874603,,,4.76054573711564e-005,3.19137554372122e-005,7.13818887349274e-005,,25,10.9165257263184,8.20891284942627,262.746058349609,,,,,,,,,,10.9157610,8.1753550,442.9448242,
,13996449.61,69906,125.205249786377,-0.0549999997019768,0,0.0106979789352417,0.999000012874603,0.00799801200866699,0.999000012874603,0.263700675048828,0.999000012874603,,,4.68127723953068e-005,3.5205757250583e-005,7.01355323182591e-005,,25,10.6979789352417,7.99801200866699,263.700675048828,,,,,,,,,,10.6931639,7.9912095,442.9448242,
,13996510.16,69906,122.16849899292,-0.0549999997019768,0,0.0104706948852539,0.999000012874603,0.00778822843551636,0.999000012874603,0.264854125976563,0.999000012874603,,,4.9742930913979e-005,3.06888785484321e-005,4.87543568854233e-005,,25,10.4706948852539,7.78822843551636,264.854125976563,,,,,,,,,,10.4146557,7.8611631,442.9448242,
,13996559.89,69906,119.693801879883,-0.0549999997019768,0,0.0102680881500244,0.999000012874603,0.00762060892105103,0.999000012874603,0.265610893554688,0.999000012874603,,,4.13514106544121e-005,2.40467574864063e-005,5.8666190852181e-005,,25,10.2680881500244,7.62060892105103,265.610893554687,,,,,,,,,,10.2683172,7.6558490,442.9448242,
,13996619.67,69906,116.70959854126,-0.0549999997019768,0,0.0100259171676636,0.999000012874603,0.00740764490127564,0.999000012874603,0.266724146728516,0.999000012874603,,,5.10436996736555e-005,2.68821641665093e-005,6.05368041017363e-005,,25,10.0259171676636,7.40764490127563,266.724146728516,,,,,,,,,,10.0324917,7.3967886,442.9448242,
,13996669.55,69906,114.21549987793,-0.0549999997019768,0,0.00983305870056152,0.999000012874603,0.00721681602478027,0.999000012874603,0.267584311523438,0.999000012874603,,,4.77840007877529e-005,2.80127681144456e-005,5.81565788954366e-005,,25,9.83305870056152,7.21681602478027,267.584311523438,,,,,,,,,,9.8452129,7.1985474,442.9448242,
,13996729.61,69906,111.215400695801,-0.0549999997019768,0,0.00958392890930176,0.999000012874603,0.00700172018051148,0.999000012874603,0.268778232421875,0.999000012874603,,,4.58871156001884e-005,2.57332134821777e-005,6.21674112231877e-005,,25,9.58392890930176,7.00172018051147,268.778232421875,,,,,,,,,,9.5512066,7.0587559,442.9448242,
,13996790.19,69906,108.171298980713,-0.0549999997019768,0,0.00931780261993408,0.999000012874603,0.00675695873260498,0.999000012874603,0.269894978027344,0.999000012874603,,,5.06826752672453e-005,2.62575345709616e-005,7.56868397929888e-005,,25,9.31780261993408,6.75695873260498,269.894978027344,,,,,,,,,,9.3948574,6.7690368,442.9448242,
,13996850.28,69906,105.180599212646,-0.0549999997019768,0,0.00904374420166016,0.999000012874603,0.00650387010574341,0.999000012874603,0.271202247314453,0.999000012874603,,,5.83942861311925e-005,2.3607883163474e-005,4.44738082443541e-005,,25,9.04374420166016,6.50387010574341,271.202247314453,,,,,,,,,,9.0469542,6.5109792,442.9448242,
,13996900.33,69906,102.679698944092,-0.0549999997019768,0,0.00881109912872315,0.999000012874603,0.00628133560180664,0.999000012874603,0.272374617919922,0.999000012874603,,,5.26246887188384e-005,2.77270397441091e-005,8.74715762629176e-005,,25,8.81109912872314,6.28133560180664,272.374617919922,,,,,,,,,,8.8918190,6.2852340,442.9448242,
,13996959.89,69906,99.7048530578613,-0.0549999997019768,0,0.00849113098144531,0.999000012874603,0.00599954103469849,0.999000012874603,0.273801123046875,0.999000012874603,,,5.75736423238237e-005,2.77529822144865e-005,5.86423426682114e-005,,25,8.49113098144531,5.99954103469849,273.801123046875,,,,,,,,,,8.5703363,6.0282874,442.9448242,
,13997021.34,69906,96.6318511962891,-0.0549999997019768,0,0.00811696624755859,0.999000012874603,0.00566290166854858,0.999000012874603,0.275280262451172,0.999000012874603,,,4.86228326809428e-005,2.24970494224993e-005,6.85379402158018e-005,,25,8.11696624755859,5.66290166854858,275.280262451172,,,,,,,,,,8.1264458,5.6915698,442.9448242,
,13997079.86,69906,93.694450378418,-0.0549999997019768,0,0.00767969772338867,0.999000012874603,0.00528713563919067,0.999000012874603,0.276604284667969,0.999000012874603,,,6.48611451557266e-005,3.42004283712534e-005,5.96353810892532e-005,,25,7.67969772338867,5.28713563919067,276.604284667969,,,,,,,,,,7.6578341,5.3702307,442.9448242,
,13997140.02,69906,90.701000213623,-0.0549999997019768,0,0.00700476816177368,0.999000012874603,0.00468905691146851,0.999000012874603,0.277774047851563,0.999000012874603,,,7.05870796410677e-005,4.78284082134312e-005,6.90625064867034e-005,,25,7.00476816177368,4.68905691146851,277.774047851563,,,,,,,,,,7.0552940,4.7468448,442.9448242,
,13997200.88,69906,87.6440505981445,-0.0549999997019768,0,8.10149805434048e-005,0.999000012874603,-2.29287166148423e-007,0.999000012874603,0.279153631591797,0.999000012874603,,,8.99676234714477e-005,3.27992723886756e-005,6.21797962690578e-005,,25,0.0810149805434048,-0.000229287166148424,279.153631591797,,,,,,,,,,0.2483950,-2.6750229e-2,442.9448242,
,13997259.72,69906,84.7260513305664,-0.0549999997019768,0,1.69672897271812e-005,0.999000012874603,1.22286762669682e-005,0.999000012874603,0.280499780273438,0.999000012874603,,,8.00107125974474e-005,2.29605916958315e-005,5.51278704204086e-005,,25,0.0169672897271812,0.0122286762669683,280.499780273438,,,,,,,,,,4.0125344e-2,-7.6429229e-3,442.9448242,
,13997319.70,69906,81.6742515563965,-0.0549999997019768,0,3.53113108733669e-005,0.999000012874603,7.03168963082135e-006,0.999000012874603,0.282031223144531,0.999000012874603,,,7.89394797267636e-005,2.89871605850991e-005,8.39338269853212e-005,,25,0.0353113108733669,0.00703168963082135,282.031223144531,,,,,,,,,,-5.9234343e-2,1.3375497e-2,442.9448242,
,13997370.36,69906,79.1828498840332,-0.0549999997019768,0,3.50856666080654e-005,0.999000012874603,5.65722203813493e-006,0.999000012874603,0.283357718505859,0.999000012874603,,,9.07812538965242e-005,2.93697633700739e-005,0.000101472712930968,,25,0.0350856666080654,0.00565722203813493,283.357718505859,,,,,,,,,,0.1375766,-1.9107852e-2,442.9448242,
,13997430.19,69906,76.1714515686035,-0.0549999997019768,0,1.91119277477264e-005,0.999000012874603,8.63895484246314e-006,0.999000012874603,0.284919764404297,0.999000012874603,,,6.37972931243894e-005,2.27428559309834e-005,7.14266272578982e-005,,25,0.0191119277477264,0.00863895484246314,284.919764404297,,,,,,,,,,-3.8221549e-2,-9.5553873e-3,442.9448242,
,13997489.14,69906,73.1838989257813,-0.0549999997019768,0,2.0563632696867e-005,0.999000012874603,-3.59297371469438e-006,0.999000012874603,0.286467407226563,0.999000012874603,,,7.86648330343309e-005,2.61107068920235e-005,6.37008856285366e-005,,25,0.020563632696867,-0.00359297371469438,286.467407226563,,,,,,,,,,0.1070275,-3.4401700e-2,442.9448242,
,13997550.05,69906,70.1819496154785,-0.0549999997019768,0,3.01929761841893e-005,0.999000012874603,-7.03225271776319e-006,0.999000012874603,0.287969593505859,0.999000012874603,,,8.61691730942396e-005,2.29425789767008e-005,6.85877365594524e-005,,25,0.0301929761841893,-0.00703225271776319,287.969593505859,,,,,,,,,,-7.6443106e-3,-3.8221553e-3,442.9448242,
,13997610.27,69906,67.1956481933594,-0.0549999997019768,0,2.98927883058786e-005,0.999000012874603,9.63203843683005e-006,0.999000012874603,0.289701444091797,0.999000012874603,,,6.9227661655958e-005,3.20296411487457e-005,0.000123662626244373,,25,0.0298927883058786,0.00963203843683004,289.701444091797,,,,,,,,,,1.9109132e-2,9.1723837e-2,442.9448242,
,13997670.28,69906,64.1718006134033,-0.0549999997019768,0,2.83665049728006e-005,0.999000012874603,-3.21002848446369e-006,0.999000012874603,0.291317481689453,0.999000012874603,,,0.00010657290501863,3.92903550867245e-005,7.13256834674709e-005,,25,0.0283665049728006,-0.00321002848446369,291.317481689453,,,,,,,,,,-3.0585425e-2,1.9115891e-3,442.9448242,
,13997728.61,69906,61.1940994262695,-0.0549999997019768,0,3.01970670139417e-005,0.999000012874603,3.59296966809779e-006,0.999000012874603,0.292842856445312,0.999000012874603,,,9.97809234444638e-005,3.50855522814456e-005,7.26142066785034e-005,,25,0.0301970670139417,0.00359296966809779,292.842856445313,,,,,,,,,,0.1490826,-5.7339448e-2,442.9448242,
,13997789.52,69906,58.214900970459,-0.0549999997019768,0,3.54715278372168e-005,0.999000012874603,-6.10831286758185e-007,0.999000012874603,0.294539318847656,0.999000012874603,,,9.80143969998585e-005,4.46307788272323e-005,9.44732540001482e-005,,25,0.0354715278372169,-0.000610831286758184,294.539318847656,,,,,,,,,,-1.9111507e-2,-5.7334518e-3,442.9448242,
,13997849.89,69906,55.198450088501,-0.0549999997019768,0,3.1566295675002e-005,0.999000012874603,-5.04376749973744e-006,0.999000012874603,0.296133870849609,0.999000012874603,,,0.000108911614179382,3.58747587792915e-005,5.59806553714287e-005,,25,0.031566295675002,-0.00504376749973744,296.133870849609,,,,,,,,,,-7.6449677e-2,3.6313593e-2,442.9448242,
,13997909.69,69906,52.2000007629395,-0.0549999997019768,0,7.07701295707375e-005,0.999000012874603,-6.12117312848568e-007,0.999000012874603,0.297747818603516,0.999000012874603,,,8.0077916321657e-005,3.54771257500211e-005,8.96747596984995e-005,,25,0.0707701295707375,-0.000612117312848568,297.747818603516,,,,,,,,,,5.1583812e-2,3.8210228e-2,442.9448242,
,13997958.84,69906,49.6746501922607,-0.0549999997019768,0,2.72883628122509e-005,0.999000012874603,7.03229479957372e-006,0.999000012874603,0.299170627441406,0.999000012874603,,,0.000122092217973659,2.78328749302788e-005,8.32480147375713e-005,,25,0.0272883628122509,0.00703229479957372,299.170627441406,,,,,,,,,,-0.2274030,3.8218994e-2,442.9448242,
,13998009.47,69906,47.2529487609863,-0.0549999997019768,0,3.14151157438755e-005,0.999000012874603,-6.11485708504915e-007,0.999000012874603,0.300493203125,0.999000012874603,,,0.000150618371194623,3.27459392488829e-005,7.6883067895417e-005,,25,0.0314151157438755,-0.000611485708504915,300.493203125,,,,,,,,,,-0.2350401,3.4396112e-2,442.9448242,
,13998060.47,69906,44.6872997283936,-0.0549999997019768,0,6.5814995393157e-005,0.999000012874603,-5.35081340000033e-006,0.999000012874603,0.301496032714844,0.999000012874603,,,0.000149710671001626,3.81741994699456e-005,0.000570205020080634,,25,0.065814995393157,-0.00535081340000033,301.496032714844,,,,,,,,,,9.3639225e-2,1.7199041e-2,442.9448242,
,13998120.70,69906,41.6776504516602,-0.0549999997019768,0,5.12177988886833e-006,0.999000012874603,9.2497926671058e-006,0.999000012874603,0.302660238037109,0.999000012874603,,,0.000155329939616336,4.55364585555316e-005,8.97067930659098e-005,,25,0.00512177988886833,0.00924979266710579,302.660238037109,,,,,,,,,,0.1280446,4.9688969e-2,442.9448242,
,13998178.78,69906,38.7182006835938,-0.0549999997019768,0,0.000108634984977543,0.999000012874603,-1.0855853962712e-005,0.999000012874603,0.304306848144531,0.999000012874603,,,0.000163662742074058,3.87401516522039e-005,8.46447420868657e-005,,25,0.108634984977543,-0.010855853962712,304.306848144531,,,,,,,,,,0.3249111,1.9112419e-3,442.9448242,
,13998229.47,69906,36.2110004425049,-0.0549999997019768,0,2.23209621245041e-005,0.999000012874603,-6.87974838539958e-006,0.999000012874603,0.305637752685547,0.999000012874603,,,0.000256132363641465,3.73939513854908e-005,9.17799295285485e-005,,25,0.0223209621245042,-0.00687974838539958,305.637752685547,,,,,,,,,,0.3153218,-0.1012852,442.9448242,
,13998289.50,69906,33.2331504821777,-0.0549999997019768,0,5.58708267007023e-005,0.999000012874603,-2.29292018339037e-007,0.999000012874603,0.3072333984375,0.999000012874603,,,0.000203854613913873,3.97892015265209e-005,8.66098545962242e-005,,25,0.0558708267007023,-0.000229292018339038,307.2333984375,,,,,,,,,,0.2655966,-1.9107671e-2,442.9448242,
,13998331.06,69906,31.1642999649048,-0.0549999997019768,0,6.6873727068305e-005,0.999000012874603,1.49808584991843e-005,0.999000012874603,0.308370416259766,0.999000012874603,,,0.000259275505477489,4.58075421914614e-005,9.97026666765808e-005,,25,0.066873727068305,0.0149808584991843,308.370416259766,,,,,,,,,,7.8341454e-2,-4.5858409e-2,442.9448242,
,13998390.11,69906,28.2021999359131,-0.0549999997019768,0,0.000114052016250789,0.999000012874603,-3.43990853987635e-006,0.999000012874603,0.310030318603516,0.999000012874603,,,0.000277934903583216,5.86293611910121e-005,9.11318234743158e-005,,25,0.114052016250789,-0.00343990853987634,310.030318603516,,,,,,,,,,-0.2484377,-3.8221187e-3,442.9448242,
,13998440.13,69906,25.6812000274658,-0.0549999997019768,0,5.58178576268256e-005,0.999000012874603,3.36436597630382e-006,0.999000012874603,0.311473483886719,0.999000012874603,,,0.000344896091981972,6.54422646743109e-005,9.38121805419092e-005,,25,0.0558178576268256,0.00336436597630382,311.473483886719,,,,,,,,,,0.4492191,5.5435549e-2,442.9448242,
,13998499.94,69906,22.6954002380371,-0.0549999997019768,0,0.000133603372313082,0.999000012874603,6.26743333414197e-006,0.999000012874603,0.312931602783203,0.999000012874603,,,0.000381145825718623,6.51211666194341e-005,0.000121552103086167,,25,0.133603372313082,0.00626743333414197,312.931602783203,,,,,,,,,,-2.4840444e-2,-5.1591694e-2,442.9448242,
,13998559.27,69906,19.7157001495361,-0.0549999997019768,0,5.60354775562883e-005,0.999000012874603,2.23988992348313e-005,0.999000012874603,0.314526934814453,0.999000012874603,,,0.000331699949231914,4.02727138269248e-005,0.000172899380563817,,25,0.0560354775562882,0.0223988992348313,314.526934814453,,,,,,,,,,-0.3306322,6.3068576e-2,442.9448242,
,13998620.94,69906,16.6357498168945,-0.0549999997019768,0,3.70724253356457e-005,0.999000012874603,-1.49054098967463e-005,0.999000012874603,0.316108291015625,0.999000012874603,,,0.000320286570561794,9.77345749772421e-005,0.000126358061227558,,25,0.0370724253356457,-0.0149054098967463,316.108291015625,,,,,,,,,,3.2486144e-2,6.6883236e-2,442.9448242,
,13998680.20,69906,13.7081503868103,-0.0549999997019768,0,0.000210158144831657,0.999000012874603,-4.41874935664237e-005,0.999000012874603,0.317692459716797,0.999000012874603,,,0.000456017315131604,7.16366235057496e-005,0.000157862606791974,,25,0.210158144831657,-0.0441874935664237,317.692459716797,,,,,,,,,,0.7281762,-7.6448950e-3,442.9448242,
,13998741.27,69906,10.6364002227783,-0.0549999997019768,0,0.000175162956863642,0.999000012874603,-2.75245068594813e-005,0.999000012874603,0.319441937255859,0.999000012874603,,,0.000580184303016762,9.68275775957458e-005,0.000190534915789958,,25,0.175162956863642,-0.0275245068594813,319.441937255859,,,,,,,,,,-4.2051341e-2,-0.1185083,442.9448242,
,13998758.80,69906,9.91794967651367,-0.0549999997019768,0,7.48408272862434e-005,0.999000012874603,-3.71483070403337e-005,0.999000012874603,0.319785134277344,0.999000012874603,,,0.000610414738510103,8.14934632246532e-005,0.000153619923550468,,25,0.0748408272862434,-0.0371483070403337,319.785134277344,,,,,,,,,,1.2577175,-2.1025671e-2,442.9448242,